[2.080s] Traceback (most recent call last):
  File "/usr/lib/python3/dist-packages/colcon_core/executor/__init__.py", line 91, in __call__
    rc = await self.task(*args, **kwargs)
  File "/usr/lib/python3/dist-packages/colcon_core/task/__init__.py", line 93, in __call__
    return await task_method(*args, **kwargs)
  File "/usr/lib/python3/dist-packages/colcon_ros/task/ament_python/build.py", line 51, in build
    setup_py_data = get_setup_data(self.context.pkg, env)
  File "/usr/lib/python3/dist-packages/colcon_core/task/python/__init__.py", line 20, in get_setup_data
    return dict(pkg.metadata[key](env))
  File "/usr/lib/python3/dist-packages/colcon_ros/package_augmentation/ros_ament_python.py", line 57, in getter
    return get_setup_information(
  File "/usr/lib/python3/dist-packages/colcon_python_setup_py/package_identification/python_setup_py.py", line 241, in get_setup_information
    _setup_information_cache[hashable_env] = _get_setup_information(
  File "/usr/lib/python3/dist-packages/colcon_python_setup_py/package_identification/python_setup_py.py", line 288, in _get_setup_information
    result = subprocess.run(
  File "/usr/lib/python3.8/subprocess.py", line 493, in run
    with Popen(*popenargs, **kwargs) as process:
  File "/usr/lib/python3.8/subprocess.py", line 858, in __init__
    self._execute_child(args, executable, preexec_fn, close_fds,
  File "/usr/lib/python3.8/subprocess.py", line 1704, in _execute_child
    raise child_exception_type(errno_num, err_msg, err_filename)
FileNotFoundError: [Errno 2] No such file or directory: '/mnt/nvme0n1/f1tenth_ws/src/Testdriving'
